<?xml version="1.0"?><robot name="robots/1"><link name="8325804"><inertial><origin xyz="-5.421010862427522e-20 -1.6263032587282567e-19 0.0010000000000000002" rpy="2.805222691937998 -0.4637349355377679 -1.8947365852651439"/><mass value="4.188790204786391e-11"/><inertia ixx="1.675516081914556e-17" ixy="0" ixz="0" iyy="1.675516081914556e-17" iyz="0" izz="1.675516081914556e-17"/></inertial><collision><origin xyz="-5.421010862427522e-20 -1.6263032587282567e-19 0.0010000000000000002" rpy="2.805222691937998 -0.4637349355377679 -1.8947365852651439"/><geometry><sphere radius="0.001"/></geometry></collision></link><link name="4735681"><inertial><origin xyz="-3.469446951953614e-18 -1.214306433183765e-17 0.08472517387841258" rpy="2.1438173446275064 0.22177047651158308 0.4031494746491941"/><mass value="0.6946108199226944"/><inertia ixx="0.0019944652455508296" ixy="0" ixz="0" iyy="0.0019944652455508296" iyz="0" izz="0.0019944652455508296"/></inertial><collision><origin xyz="-3.469446951953614e-18 -1.214306433183765e-17 0.08472517387841258" rpy="2.1438173446275064 0.22177047651158308 0.4031494746491941"/><geometry><sphere radius="0.08472517387841255"/></geometry></collision></link><link name="4064029"><inertial><origin xyz="-0.013392437970720003 6.841951323297693e-05 0.036824153984054794" rpy="1.5707963267948846 1.5656875543561597 1.5656875543561477"/><mass value="0.32657421908334666"/><inertia ixx="0.0003600348756754367" ixy="0" ixz="0" iyy="0.0003600348756754367" iyz="0" izz="0.00022142031140993636"/></inertial><collision><origin xyz="-0.013392437970720003 6.841951323297693e-05 0.036824153984054794" rpy="1.5707963267948846 1.5656875543561597 1.5656875543561477"/><geometry><cylinder radius="0.0368241539840548" length="0.09571551589530464"/></geometry></collision></link><link name="5314437"><inertial><origin xyz="-8.890457814381136e-18 -1.0408340855860843e-17 0.04736004193466575" rpy="2.4511824641190803 -0.64318517469432 -1.4944830101829576"/><mass value="0.14423106891506815"/><inertia ixx="0.00012940259033819833" ixy="0" ixz="0" iyy="0.00012940259033819833" iyz="0" izz="0.00012940259033819833"/></inertial><collision><origin xyz="-8.890457814381136e-18 -1.0408340855860843e-17 0.04736004193466575" rpy="2.4511824641190803 -0.64318517469432 -1.4944830101829576"/><geometry><sphere radius="0.047360041934665746"/></geometry></collision></link><link name="1844789"><inertial><origin xyz="-0.01302201858425922 5.847181364028571e-06 0.009928035035897393" rpy="1.5707963267947602 1.5703473041696234 1.570347304169487"/><mass value="0.022543488066187885"/><inertia ixx="1.8224520051453555e-05" ixy="0" ixz="0" iyy="1.8224520051453555e-05" iyz="0" izz="1.111009366082133e-06"/></inertial><collision><origin xyz="-0.01302201858425922 5.847181364028571e-06 0.009928035035897393" rpy="1.5707963267947602 1.5703473041696234 1.570347304169487"/><geometry><cylinder radius="0.009928035035897387" length="0.09698090677467489"/></geometry></collision></link><link name="3416624"><inertial><origin xyz="0.006343136646001411 0.018183987579849615 0.06582443936436896" rpy="-1.1730686913247659 0.3111558062875473 -0.20771253388075261"/><mass value="0.8541329457565685"/><inertia ixx="0.0020295629099782607" ixy="0" ixz="0" iyy="0.001257342235037602" iyz="0" izz="0.0020295629099782607"/></inertial><collision><origin xyz="0.006343136646001411 0.018183987579849615 0.06582443936436896" rpy="-1.1730686913247659 0.3111558062875473 -0.20771253388075261"/><geometry><capsule radius="0.05818503294385344" length="0.04143685882263688"/></geometry></collision></link><joint name="2951283" type="continuous"><origin xyz=" 0.0001594  -0.00093199  0.00132557" rpy="1.234723064479196 0.1600822464236807 0.11376816642899787"/><parent link="8325804"/><child link="4735681"/><axis xyz="0 0 1"/><dynamics damping="0.1" friction="0.1"/><limit lower="0" upper="0" effort="1" velocity="1"/></joint><joint name="2574580" type="fixed"><origin xyz=" 0.04142879 -0.06828364  0.0564523 " rpy="1.963356144709571 0.5109183332715397 0.7451047538495431"/><parent link="4735681"/><child link="4064029"/><axis xyz="0 0 0"/><dynamics damping="0" friction="0"/><limit lower="0" upper="0" effort="10" velocity="10"/></joint><joint name="9958721" type="revolute"><origin xyz="-1.94187710e-02  2.18095641e-04  1.91914661e-07" rpy="-3.1383641802364513 1.6493650525514176e-05 -0.010217518252676087"/><parent link="4064029"/><child link="5314437"/><axis xyz="0 0 1"/><dynamics damping="0.1" friction="0.1"/><limit lower="0" upper="6.283185307179586" effort="1" velocity="1"/></joint><joint name="3283812" type="continuous"><origin xyz="-0.00912397 -0.04638031  0.04442856" rpy="1.6339176954236625 -0.19386335686687087 -0.2064165452742034"/><parent link="5314437"/><child link="1844789"/><axis xyz="0 0 1"/><dynamics damping="0.1" friction="0.1"/><limit lower="0" upper="0" effort="1" velocity="1"/></joint><joint name="7781930" type="fixed"><origin xyz="-5.21927538e-02  3.11575316e-05  3.00292219e-09" rpy="-3.1408148761281254 3.492396660048439e-07 -0.0008980451148039202"/><parent link="1844789"/><child link="3416624"/><axis xyz="0 0 0"/><dynamics damping="0" friction="0"/><limit lower="0" upper="0" effort="10" velocity="10"/></joint></robot>