<?xml version="1.0"?><robot name="robots/2"><link name="8325804"><inertial><origin xyz="-5.421010862427522e-20 -1.6263032587282567e-19 0.0010000000000000002" rpy="2.805222691937998 -0.4637349355377679 -1.8947365852651439"/><mass value="4.188790204786391e-11"/><inertia ixx="1.675516081914556e-17" ixy="0" ixz="0" iyy="1.675516081914556e-17" iyz="0" izz="1.675516081914556e-17"/></inertial><collision><origin xyz="-5.421010862427522e-20 -1.6263032587282567e-19 0.0010000000000000002" rpy="2.805222691937998 -0.4637349355377679 -1.8947365852651439"/><geometry><sphere radius="0.001"/></geometry></collision></link><link name="4735681"><inertial><origin xyz="0.0003859009649895602 -0.000859723857981453 0.019219085364634993" rpy="-0.0 -1.5707963267948966 0.0"/><mass value="0.0017684719404513817"/><inertia ixx="2.224821094818478e-07" ixy="0" ixz="0" iyy="3.482064350058342e-07" iyz="0" izz="1.352044015022116e-07"/></inertial><collision><origin xyz="0.0003859009649895602 -0.000859723857981453 0.019219085364634993" rpy="-0.0 -1.5707963267948966 0.0"/><geometry><box size="0.038438170729269985 0.029753460654447228 0.005671297731744318"/></geometry></collision></link><link name="4668302"><inertial><origin xyz="8.673617379884035e-18 2.688821387764051e-17 0.09571551589530464" rpy="2.200131984542108 -0.14975648688192605 -0.2927264225948435"/><mass value="1.9117785545564248"/><inertia ixx="0.007005873089650279" ixy="0" ixz="0" iyy="0.007005873089650279" iyz="0" izz="0.007005873089650279"/></inertial><collision><origin xyz="8.673617379884035e-18 2.688821387764051e-17 0.09571551589530464" rpy="2.200131984542108 -0.14975648688192605 -0.2927264225948435"/><geometry><sphere radius="0.09571551589530464"/></geometry></collision></link><link name="9160297"><inertial><origin xyz="0.03638939428816756 0.025626649840692874 0.0009394900218177615" rpy="0 3.141592653589793 0"/><mass value="0.018000647853530338"/><inertia ixx="1.4546091311274979e-05" ixy="0" ixz="0" iyy="1.4546091311274979e-05" iyz="0" izz="2.908159054332187e-05"/></inertial><collision><origin xyz="0.03638939428816756 0.025626649840692874 0.0009394900218177615" rpy="0 3.141592653589793 0"/><geometry><cylinder radius="0.05684339488686485" length="0.0018789800436355142"/></geometry></collision></link><link name="1917999"><inertial><origin xyz="-6.938893903907228e-18 -1.734723475976807e-18 0.0750686141218456" rpy="-1.7382749703381017 0.25492532056715234 -0.30099212932021757"/><mass value="1.6992584420914167"/><inertia ixx="0.0038303302822272354" ixy="0" ixz="0" iyy="0.0038303302822272354" iyz="0" izz="0.0038303302822272354"/></inertial><collision><origin xyz="-6.938893903907228e-18 -1.734723475976807e-18 0.0750686141218456" rpy="-1.7382749703381017 0.25492532056715234 -0.30099212932021757"/><geometry><sphere radius="0.07506861412184562"/></geometry></collision></link><link name="7526257"><inertial><origin xyz="-1.0408340855860843e-17 6.938893903907228e-18 0.06747523222590207" rpy="1.6837392975685865 0.5497226856868193 0.611764262021192"/><mass value="0.0174644118202432"/><inertia ixx="3.1805536878996424e-05" ixy="0" ixz="0" iyy="3.1805536878996424e-05" iyz="0" izz="3.1805536878996424e-05"/></inertial><collision><origin xyz="-1.0408340855860843e-17 6.938893903907228e-18 0.06747523222590207" rpy="1.6837392975685865 0.5497226856868193 0.611764262021192"/><geometry><sphere radius="0.06747523222590207"/></geometry></collision></link><joint name="2527987" type="revolute"><origin xyz="-0.00058145 -0.00054679  0.00160244" rpy="0.7370101521161919 -0.6205093960536117 -0.2463487383853033"/><parent link="8325804"/><child link="4735681"/><axis xyz="0 0 1"/><dynamics damping="0.1" friction="0.1"/><limit lower="0" upper="6.283185307179586" effort="1" velocity="1"/></joint><joint name="7329820" type="fixed"><origin xyz=" 0.00053562 -0.01258534  0.03843817" rpy="0 0 0"/><parent link="4735681"/><child link="4668302"/><axis xyz="0 0 0"/><dynamics damping="0" friction="0"/><limit lower="0" upper="0" effort="10" velocity="10"/></joint><joint name="86107" type="fixed"><origin xyz="0.08061522 0.03688976 0.13179586" rpy="-0.7964900551149955 1.0014207784228513 -0.4525773058843282"/><parent link="4668302"/><child link="9160297"/><axis xyz="0 0 0"/><dynamics damping="0" friction="0"/><limit lower="0" upper="0" effort="10" velocity="10"/></joint><joint name="4295565" type="fixed"><origin xyz="3.50301186e-02 6.44194645e-02 4.28995226e-18" rpy="0 3.141592653589793 0"/><parent link="9160297"/><child link="1917999"/><axis xyz="0 0 0"/><dynamics damping="0" friction="0"/><limit lower="0" upper="0" effort="10" velocity="10"/></joint><joint name="4219081" type="continuous"><origin xyz="0.00300498 0.07421909 0.06421532" rpy="-1.7160003618167112 0.040040437173014407 -0.04631943652625425"/><parent link="1917999"/><child link="7526257"/><axis xyz="0 0 1"/><dynamics damping="0.1" friction="0.1"/><limit lower="0" upper="0" effort="1" velocity="1"/></joint></robot>