<?xml version="1.0"?><robot name="robots/2"><link name="8325804"><inertial><origin xyz="-5.421010862427522e-20 -1.6263032587282567e-19 0.0010000000000000002" rpy="2.805222691937998 -0.4637349355377679 -1.8947365852651439"/><mass value="4.188790204786391e-11"/><inertia ixx="1.675516081914556e-17" ixy="0" ixz="0" iyy="1.675516081914556e-17" iyz="0" izz="1.675516081914556e-17"/></inertial><collision><origin xyz="-5.421010862427522e-20 -1.6263032587282567e-19 0.0010000000000000002" rpy="2.805222691937998 -0.4637349355377679 -1.8947365852651439"/><geometry><sphere radius="0.001"/></geometry></collision></link><link name="4735681"><inertial><origin xyz="0.0003859009649895602 -0.000859723857981453 0.019219085364634993" rpy="-0.0 -1.5707963267948966 0.0"/><mass value="0.0017684719404513817"/><inertia ixx="2.224821094818478e-07" ixy="0" ixz="0" iyy="3.482064350058342e-07" iyz="0" izz="1.352044015022116e-07"/></inertial><collision><origin xyz="0.0003859009649895602 -0.000859723857981453 0.019219085364634993" rpy="-0.0 -1.5707963267948966 0.0"/><geometry><box size="0.038438170729269985 0.029753460654447228 0.005671297731744318"/></geometry></collision></link><link name="4668302"><inertial><origin xyz="-0.005149561620180043 -0.0029167009442045977 0.09948655350160623" rpy="0.6583396269107812 -0.8239178279343984 -0.29634247601746494"/><mass value="2.1220262946419868"/><inertia ixx="0.008642250893943704" ixy="0" ixz="0" iyy="0.007968961218316275" iyz="0" izz="0.008642250893943704"/></inertial><collision><origin xyz="-0.005149561620180043 -0.0029167009442045977 0.09948655350160623" rpy="0.6583396269107812 -0.8239178279343984 -0.29634247601746494"/><geometry><capsule radius="0.09571551589530464" length="0.014035078041264516"/></geometry></collision></link><link name="9160297"><inertial><origin xyz="-0.024822251955442173 -0.006920565896708409 0.03088177485379385" rpy="-0.0 1.5707963267948966 0.0"/><mass value="0.22011334635223626"/><inertia ixx="0.00013978686262048755" ixy="0" ixz="0" iyy="0.00013869613078695231" iyz="0" izz="0.0001385372730133524"/></inertial><collision><origin xyz="-0.024822251955442173 -0.006920565896708409 0.03088177485379385" rpy="-0.0 1.5707963267948966 0.0"/><geometry><box size="0.06176354970758771 0.06120957227224214 0.0616933996874757"/></geometry></collision></link><link name="1917999"><inertial><origin xyz="-0.017242041194504672 0.024733358640024444 0.030391533435773384" rpy="0 3.141592653589793 0"/><mass value="1.0319173404817041"/><inertia ixx="0.001771498663838849" ixy="0" ixz="0" iyy="0.001771498663838849" iyz="0" izz="0.00290758025684552"/></inertial><collision><origin xyz="-0.017242041194504672 0.024733358640024444 0.030391533435773384" rpy="0 3.141592653589793 0"/><geometry><cylinder radius="0.07506861412184562" length="0.060783066871546776"/></geometry></collision></link><link name="7664932"><inertial><origin xyz="0.03400349776096143 -0.005066442411910259 0.04995880147935469" rpy="0.27095484477390835 1.0628349659804246 0.15991340450150332"/><mass value="0.23650830993001762"/><inertia ixx="0.00047874249553790844" ixy="0" ixz="0" iyy="0.00011060558672615632" iyz="0" izz="0.00047874249553790844"/></inertial><collision><origin xyz="0.03400349776096143 -0.005066442411910259 0.04995880147935469" rpy="0.27095484477390835 1.0628349659804246 0.15991340450150332"/><geometry><capsule radius="0.03172017420692961" length="0.0778345482025909"/></geometry></collision></link><joint name="2527987" type="continuous"><origin xyz="-0.00058145 -0.00054679  0.00160244" rpy="0.7370101521161919 -0.6205093960536117 -0.2463487383853033"/><parent link="8325804"/><child link="4735681"/><axis xyz="0 0 1"/><dynamics damping="0.1" friction="0.1"/><limit lower="0" upper="0" effort="1" velocity="1"/></joint><joint name="7329820" type="fixed"><origin xyz=" 0.00322155 -0.01019242  0.01820433" rpy="-0.0 1.5707963267948963 0.0"/><parent link="4735681"/><child link="4668302"/><axis xyz="0 0 0"/><dynamics damping="0" friction="0"/><limit lower="0" upper="0" effort="10" velocity="10"/></joint><joint name="86107" type="revolute"><origin xyz=" 0.06016102 -0.01880747  0.16778593" rpy="0.24650908055781443 0.7035514966856717 0.09087760815071198"/><parent link="4668302"/><child link="9160297"/><axis xyz="0 0 1"/><dynamics damping="0.1" friction="0.1"/><limit lower="0" upper="6.283185307179586" effort="1" velocity="1"/></joint><joint name="341845" type="continuous"><origin xyz="-4.58615777e-02 -2.25641661e-02 -1.01833159e-17" rpy="0 3.141592653589793 0"/><parent link="9160297"/><child link="1917999"/><axis xyz="0 0 1"/><dynamics damping="0.1" friction="0.1"/><limit lower="0" upper="0" effort="1" velocity="1"/></joint><joint name="6687090" type="continuous"><origin xyz="-0.09230401  0.0257323   0.05840111" rpy="-1.570796326794892 -1.5574889290609542 1.5574889290609495"/><parent link="1917999"/><child link="7664932"/><axis xyz="0 0 1"/><dynamics damping="0.1" friction="0.1"/><limit lower="0" upper="0" effort="1" velocity="1"/></joint></robot>