<?xml version="1.0"?><robot name="robots/3"><link name="8325804"><inertial><origin xyz="-5.421010862427522e-20 -1.6263032587282567e-19 0.0010000000000000002" rpy="2.805222691937998 -0.4637349355377679 -1.8947365852651439"/><mass value="4.188790204786391e-11"/><inertia ixx="1.675516081914556e-17" ixy="0" ixz="0" iyy="1.675516081914556e-17" iyz="0" izz="1.675516081914556e-17"/></inertial><collision><origin xyz="-5.421010862427522e-20 -1.6263032587282567e-19 0.0010000000000000002" rpy="2.805222691937998 -0.4637349355377679 -1.8947365852651439"/><geometry><sphere radius="0.001"/></geometry></collision></link><link name="4735681"><inertial><origin xyz="-0.004243002915481152 -8.686005749926893e-06 0.08472517387841255" rpy="-1.5707963267948666 1.568749193246015 -1.5687491932459852"/><mass value="0.3834168207079572"/><inertia ixx="0.0008123126948834758" ixy="0" ixz="0" iyy="0.0008123126948834758" iyz="0" izz="0.0013761510430162923"/></inertial><collision><origin xyz="-0.004243002915481152 -8.686005749926893e-06 0.08472517387841255" rpy="-1.5707963267948666 1.568749193246015 -1.5687491932459852"/><geometry><cylinder radius="0.08472517387841255" length="0.062356369678597236"/></geometry></collision></link><link name="4064029"><inertial><origin xyz="-0.0066267721403629725 0.0332134558241 0.007017539020632256" rpy="-0.0 1.5707963267948966 0.0"/><mass value="0.04632131030305521"/><inertia ixx="9.418779224940949e-06" ixy="0" ixz="0" iyy="2.9983405047040956e-05" iyz="0" izz="3.788142928536643e-05"/></inertial><collision><origin xyz="-0.0066267721403629725 0.0332134558241 0.007017539020632256" rpy="-0.0 1.5707963267948966 0.0"/><geometry><box size="0.014035078041264516 0.08700872583584364 0.04736080452737105"/></geometry></collision></link><link name="1094020"><inertial><origin xyz="6.938893903907228e-18 8.673617379884035e-19 0.07369181771289582" rpy="1.1701647118903933 -0.39805909839098 -0.265661365778118"/><mass value="0.37267277084058664"/><inertia ixx="0.0008095174073908083" ixy="0" ixz="0" iyy="0.0008095174073908083" iyz="0" izz="0.0008095174073908083"/></inertial><collision><origin xyz="6.938893903907228e-18 8.673617379884035e-19 0.07369181771289582" rpy="1.1701647118903933 -0.39805909839098 -0.265661365778118"/><geometry><sphere radius="0.07369181771289582"/></geometry></collision></link><link name="1917999"><inertial><origin xyz="0.011009040270298493 -0.009711263889999065 0.0019212713236367342" rpy="-1.5707963267948966 0.0 0.0"/><mass value="0.007596923368177205"/><inertia ixx="3.2157731142543376e-06" ixy="0" ixz="0" iyy="6.782293530919816e-07" iyz="0" izz="2.5562386930772484e-06"/></inertial><collision><origin xyz="0.011009040270298493 -0.009711263889999065 0.0019212713236367342" rpy="-1.5707963267948966 0.0 0.0"/><geometry><box size="0.032504722900835246 0.0038425426472734727 0.06342740579573351"/></geometry></collision></link><link name="7526257"><inertial><origin xyz="-1.0408340855860843e-17 6.938893903907228e-18 0.06747523222590207" rpy="1.6837392975685865 0.5497226856868193 0.611764262021192"/><mass value="0.0174644118202432"/><inertia ixx="3.1805536878996424e-05" ixy="0" ixz="0" iyy="3.1805536878996424e-05" iyz="0" izz="3.1805536878996424e-05"/></inertial><collision><origin xyz="-1.0408340855860843e-17 6.938893903907228e-18 0.06747523222590207" rpy="1.6837392975685865 0.5497226856868193 0.611764262021192"/><geometry><sphere radius="0.06747523222590207"/></geometry></collision></link><joint name="2951283" type="continuous"><origin xyz=" 0.0001594  -0.00093199  0.00132557" rpy="1.234723064479196 0.1600822464236807 0.11376816642899787"/><parent link="8325804"/><child link="4735681"/><axis xyz="0 0 1"/><dynamics damping="0.1" friction="0.1"/><limit lower="0" upper="0" effort="1" velocity="1"/></joint><joint name="3419595" type="fixed"><origin xyz="-9.56427679e-03 -6.18771559e-05  1.05582228e-08" rpy="3.141093420608018 1.0219979710048396e-06 0.004094266843093602"/><parent link="4735681"/><child link="4064029"/><axis xyz="0 0 0"/><dynamics damping="0" friction="0"/><limit lower="0" upper="0" effort="10" velocity="10"/></joint><joint name="86107" type="revolute"><origin xyz=" 0.00127143 -0.00505077  0.01403508" rpy="0 0 0"/><parent link="4064029"/><child link="1094020"/><axis xyz="0 0 1"/><dynamics damping="0.1" friction="0.1"/><limit lower="0" upper="6.283185307179586" effort="1" velocity="1"/></joint><joint name="4295565" type="revolute"><origin xyz="-0.05879175  0.03925359  0.0528791 " rpy="-2.0583203349234687 -0.9236469609887694 1.3822788525946863"/><parent link="1094020"/><child link="1917999"/><axis xyz="0 0 1"/><dynamics damping="0.1" friction="0.1"/><limit lower="0" upper="6.283185307179586" effort="1" velocity="1"/></joint><joint name="538112" type="fixed"><origin xyz=" 0.02650603 -0.00306118  0.00384254" rpy="0 0 0"/><parent link="1917999"/><child link="7526257"/><axis xyz="0 0 0"/><dynamics damping="0" friction="0"/><limit lower="0" upper="0" effort="10" velocity="10"/></joint></robot>